I'm sorry, but an uncaught exception occurred.

While running game code:
  File "game/script.rpy", line 405, in script
    scene bg-black fadein 2
Exception: Image 'bg-black' does not accept attributes 'fadein 2'.

-- Full Traceback ------------------------------------------------------------

Full traceback:
  File "game/script.rpy", line 405, in script
    scene bg-black fadein 2
  File "D:\GameDev\RenPy\renpy-8.0.3-sdk\renpy\ast.py", line 1542, in execute
    show_imspec(self.imspec, atl=getattr(self, "atl", None))
  File "D:\GameDev\RenPy\renpy-8.0.3-sdk\renpy\ast.py", line 1371, in show_imspec
    renpy.config.show(name,
  File "D:\GameDev\RenPy\renpy-8.0.3-sdk\renpy\exports.py", line 686, in show
    if not base.find_target() and renpy.config.missing_show:
  File "D:\GameDev\RenPy\renpy-8.0.3-sdk\renpy\display\image.py", line 414, in find_target
    self.target = target._duplicate(a)
  File "D:\GameDev\RenPy\renpy-8.0.3-sdk\renpy\display\core.py", line 397, in _duplicate
    args.extraneous()
  File "D:\GameDev\RenPy\renpy-8.0.3-sdk\renpy\display\core.py", line 265, in extraneous
    raise Exception("Image '{}' does not accept attributes '{}'.".format(
Exception: Image 'bg-black' does not accept attributes 'fadein 2'.

Windows-10-10.0.19044 AMD64
Ren'Py 8.0.3.22090809
Depths of Innsmouth 1.0
Sun Jan 29 23:58:22 2023
